<?xml version="1.0" encoding="UTF-8"?>
<!-- Generated by org.testng.reporters.JUnitReportReporter -->
<testsuite hostname="Sasi" failures="1" tests="7" name="TestRunner.Login_Func" time="15.306" errors="0" timestamp="2023-04-16T16:29:35 IST" skipped="3">
  <testcase classname="TestRunner.Login_Func" name="login_Scenario_1" time="1.994"/>
  <system-out/>
  <testcase classname="TestRunner.Login_Func" name="login_Scenario_4" time="1.935">
    <skipped/>
  </testcase> <!-- login_Scenario_4 -->
  <system-out/>
  <testcase classname="TestRunner.Login_Func" name="login_Scenario_3" time="1.899"/>
  <system-out/>
  <testcase classname="TestRunner.Login_Func" name="login_Scenario_4" time="3.801">
    <failure message="expected [Epic sadface: Username and password do not match any user in this servic] but found [Epic sadface: Username and password do not match any user in this service]" type="java.lang.AssertionError">
      <![CDATA[java.lang.AssertionError: expected [Epic sadface: Username and password do not match any user in this servic] but found [Epic sadface: Username and password do not match any user in this service]
at org.testng.Assert.fail(Assert.java:99)
at org.testng.Assert.failNotEquals(Assert.java:1037)
at org.testng.Assert.assertEqualsImpl(Assert.java:140)
at org.testng.Assert.assertEquals(Assert.java:122)
at org.testng.Assert.assertEquals(Assert.java:629)
at org.testng.Assert.assertEquals(Assert.java:639)
at TestRunner.Login_Func.login_Scenario_4(Login_Func.java:77)
at java.base/jdk.internal.reflect.NativeMethodAccessorImpl.invoke0(Native Method)
at java.base/jdk.internal.reflect.NativeMethodAccessorImpl.invoke(NativeMethodAccessorImpl.java:77)
at java.base/jdk.internal.reflect.DelegatingMethodAccessorImpl.invoke(DelegatingMethodAccessorImpl.java:43)
at java.base/java.lang.reflect.Method.invoke(Method.java:568)
at org.testng.internal.MethodInvocationHelper.invokeMethod(MethodInvocationHelper.java:133)
at org.testng.internal.TestInvoker.invokeMethod(TestInvoker.java:598)
at org.testng.internal.TestInvoker.retryFailed(TestInvoker.java:213)
at org.testng.internal.MethodRunner.runInSequence(MethodRunner.java:58)
at org.testng.internal.TestInvoker$MethodInvocationAgent.invoke(TestInvoker.java:824)
at org.testng.internal.TestInvoker.invokeTestMethods(TestInvoker.java:146)
at org.testng.internal.TestMethodWorker.invokeTestMethods(TestMethodWorker.java:146)
at org.testng.internal.TestMethodWorker.run(TestMethodWorker.java:128)
at java.base/java.util.ArrayList.forEach(ArrayList.java:1511)
at org.testng.TestRunner.privateRun(TestRunner.java:794)
at org.testng.TestRunner.run(TestRunner.java:596)
at org.testng.SuiteRunner.runTest(SuiteRunner.java:377)
at org.testng.SuiteRunner.runSequentially(SuiteRunner.java:371)
at org.testng.SuiteRunner.privateRun(SuiteRunner.java:332)
at org.testng.SuiteRunner.run(SuiteRunner.java:276)
at org.testng.SuiteRunnerWorker.runSuite(SuiteRunnerWorker.java:53)
at org.testng.SuiteRunnerWorker.run(SuiteRunnerWorker.java:96)
at org.testng.TestNG.runSuitesSequentially(TestNG.java:1212)
at org.testng.TestNG.runSuitesLocally(TestNG.java:1134)
at org.testng.TestNG.runSuites(TestNG.java:1063)
at org.testng.TestNG.run(TestNG.java:1031)
at org.testng.remote.AbstractRemoteTestNG.run(AbstractRemoteTestNG.java:115)
at org.testng.remote.RemoteTestNG.initAndRun(RemoteTestNG.java:251)
at org.testng.remote.RemoteTestNG.main(RemoteTestNG.java:77)
]]>
    </failure>
  </testcase> <!-- login_Scenario_4 -->
  <system-out/>
  <testcase classname="TestRunner.Login_Func" name="login_Scenario_4" time="1.867">
    <skipped/>
  </testcase> <!-- login_Scenario_4 -->
  <system-out/>
  <testcase classname="TestRunner.Login_Func" name="login_Scenario_2" time="1.969"/>
  <system-out/>
  <testcase classname="TestRunner.Login_Func" name="login_Scenario_4" time="1.841">
    <skipped/>
  </testcase> <!-- login_Scenario_4 -->
  <system-out/>
</testsuite> <!-- TestRunner.Login_Func -->
